<mujoco model="g1_29dof_with_hand_rev_1_0">
  <compiler angle="radian" meshdir="meshes"/>

  <!-- Mesh assets -->
  <asset>
    <mesh name="pelvis" file="pelvis.STL"/>
    <mesh name="pelvis_contour_link" file="pelvis_contour_link.STL"/>
    <mesh name="left_hip_pitch_link" file="left_hip_pitch_link.STL"/>
    <mesh name="left_hip_roll_link" file="left_hip_roll_link.STL"/>
    <mesh name="left_hip_yaw_link" file="left_hip_yaw_link.STL"/>
    <mesh name="left_knee_link" file="left_knee_link.STL"/>
    <mesh name="left_ankle_pitch_link" file="left_ankle_pitch_link.STL"/>
    <mesh name="left_ankle_roll_link" file="left_ankle_roll_link.STL"/>
    <mesh name="right_hip_pitch_link" file="right_hip_pitch_link.STL"/>
    <mesh name="right_hip_roll_link" file="right_hip_roll_link.STL"/>
    <mesh name="right_hip_yaw_link" file="right_hip_yaw_link.STL"/>
    <mesh name="right_knee_link" file="right_knee_link.STL"/>
    <mesh name="right_ankle_pitch_link" file="right_ankle_pitch_link.STL"/>
    <mesh name="right_ankle_roll_link" file="right_ankle_roll_link.STL"/>
    <mesh name="waist_yaw_link" file="waist_yaw_link_rev_1_0.STL"/>
    <mesh name="waist_roll_link" file="waist_roll_link_rev_1_0.STL"/>
    <mesh name="torso_link" file="torso_link_rev_1_0.STL"/>
    <mesh name="logo_link" file="logo_link.STL"/>
    <mesh name="head_link" file="head_link.STL"/>
    <mesh name="left_shoulder_pitch_link" file="left_shoulder_pitch_link.STL"/>
    <mesh name="left_shoulder_roll_link" file="left_shoulder_roll_link.STL"/>
    <mesh name="left_shoulder_yaw_link" file="left_shoulder_yaw_link.STL"/>
    <mesh name="left_elbow_link" file="left_elbow_link.STL"/>
    <mesh name="left_wrist_roll_link" file="left_wrist_roll_link.STL"/>
    <mesh name="left_wrist_pitch_link" file="left_wrist_pitch_link.STL"/>
    <mesh name="left_wrist_yaw_link" file="left_wrist_yaw_link.STL"/>
    <mesh name="left_hand_palm_link" file="left_hand_palm_link.STL"/>
    <mesh name="left_hand_thumb_0_link" file="left_hand_thumb_0_link.STL"/>
    <mesh name="left_hand_thumb_1_link" file="left_hand_thumb_1_link.STL"/>
    <mesh name="left_hand_thumb_2_link" file="left_hand_thumb_2_link.STL"/>
    <mesh name="left_hand_middle_0_link" file="left_hand_middle_0_link.STL"/>
    <mesh name="left_hand_middle_1_link" file="left_hand_middle_1_link.STL"/>
    <mesh name="left_hand_index_0_link" file="left_hand_index_0_link.STL"/>
    <mesh name="left_hand_index_1_link" file="left_hand_index_1_link.STL"/>
    <mesh name="right_shoulder_pitch_link" file="right_shoulder_pitch_link.STL"/>
    <mesh name="right_shoulder_roll_link" file="right_shoulder_roll_link.STL"/>
    <mesh name="right_shoulder_yaw_link" file="right_shoulder_yaw_link.STL"/>
    <mesh name="right_elbow_link" file="right_elbow_link.STL"/>
    <mesh name="right_wrist_roll_link" file="right_wrist_roll_link.STL"/>
    <mesh name="right_wrist_pitch_link" file="right_wrist_pitch_link.STL"/>
    <mesh name="right_wrist_yaw_link" file="right_wrist_yaw_link.STL"/>
    <mesh name="right_hand_palm_link" file="right_hand_palm_link.STL"/>
    <mesh name="right_hand_thumb_0_link" file="right_hand_thumb_0_link.STL"/>
    <mesh name="right_hand_thumb_1_link" file="right_hand_thumb_1_link.STL"/>
    <mesh name="right_hand_thumb_2_link" file="right_hand_thumb_2_link.STL"/>
    <mesh name="right_hand_middle_0_link" file="right_hand_middle_0_link.STL"/>
    <mesh name="right_hand_middle_1_link" file="right_hand_middle_1_link.STL"/>
    <mesh name="right_hand_index_0_link" file="right_hand_index_0_link.STL"/>
    <mesh name="right_hand_index_1_link" file="right_hand_index_1_link.STL"/>
  </asset>

  <!-- Visual assets/materials -->
  <asset>
    <texture type="skybox" builtin="flat" rgb1="0 0 0" rgb2="0 0 0" width="512" height="3072"/>
    <texture type="2d" name="groundplane" builtin="checker" mark="edge" rgb1="0.2 0.3 0.4" rgb2="0.1 0.2 0.3" markrgb="0.8 0.8 0.8" width="300" height="300"/>
    <material name="groundplane" texture="groundplane" texuniform="true" texrepeat="5 5" reflectance="0.2"/>
  </asset>

  <!-- Camera/visual setup -->
  <statistic center="1.0 0.7 1.0" extent="0.8"/>
  <visual>
    <headlight diffuse="0.6 0.6 0.6" ambient="0.1 0.1 0.1" specular="0.9 0.9 0.9"/>
    <rgba haze="0.15 0.25 0.35 1"/>
    <global azimuth="-140" elevation="-20"/>
  </visual>

  <!-- World and robot -->
  <worldbody>
    <!-- Keep ground + light here (single worldbody) -->
    <light pos="1 0 3.5" dir="0 0 -1" directional="true"/>
    <geom name="floor" size="0 0 0.05" type="plane" material="groundplane"/>

    <!-- Robot -->
    <body name="pelvis" pos="0 0 0.793">
      <inertial pos="0 0 -0.07605" quat="1 0 -0.000399148 0" mass="3.813" diaginertia="0.010549 0.0093089 0.0079184"/>
      <!-- REMOVED free base joint to make fixed-base -->
      <!-- (was: <joint name="floating_base_joint" type="free" .../>) -->

      <geom type="mesh" contype="0" conaffinity="0" group="1" density="0" rgba="0.2 0.2 0.2 1" mesh="pelvis"/>
      <geom type="mesh" contype="0" conaffinity="0" group="1" density="0" rgba="0.7 0.7 0.7 1" mesh="pelvis_contour_link"/>
      <geom type="mesh" rgba="0.7 0.7 0.7 1" mesh="pelvis_contour_link"/>
      <site name="imu_in_pelvis" size="0.01" pos="0.04525 0 -0.08339"/>

      <!-- ... (LEFT LEG CHAIN UNCHANGED) ... -->

      <!-- ... (RIGHT LEG CHAIN UNCHANGED) ... -->

      <body name="waist_yaw_link">
        <inertial pos="0.003494 0.000233 0.018034" quat="0.289697 0.591001 -0.337795 0.672821" mass="0.214" diaginertia="0.000163531 0.000107714 0.000102205"/>
        <joint name="waist_yaw_joint" pos="0 0 0" axis="0 0 1" range="-2.618 2.618" actuatorfrcrange="-88 88"/>
        <geom type="mesh" contype="0" conaffinity="0" group="1" density="0" rgba="0.7 0.7 0.7 1" mesh="waist_yaw_link"/>
        <body name="waist_roll_link" pos="-0.0039635 0 0.044">
          <inertial pos="0 2.3e-05 0" quat="0.5 0.5 -0.5 0.5" mass="0.086" diaginertia="8.245e-06 7.079e-06 6.339e-06"/>
          <joint name="waist_roll_joint" pos="0 0 0" axis="1 0 0" range="-0.52 0.52" actuatorfrcrange="-50 50"/>
          <geom type="mesh" contype="0" conaffinity="0" group="1" density="0" rgba="0.7 0.7 0.7 1" mesh="waist_roll_link"/>
          <body name="torso_link">
            <inertial pos="0.00203158 0.000339683 0.184568" quat="0.999803 -6.03319e-05 0.0198256 0.00131986" mass="7.818" diaginertia="0.121847 0.109825 0.0273735"/>
            <joint name="waist_pitch_joint" pos="0 0 0" axis="0 1 0" range="-0.52 0.52" actuatorfrcrange="-50 50"/>
            <geom type="mesh" contype="0" conaffinity="0" group="1" density="0" rgba="0.7 0.7 0.7 1" mesh="torso_link"/>
            <geom type="mesh" rgba="0.7 0.7 0.7 1" mesh="torso_link"/>
            <geom pos="0.0039635 0 -0.044" quat="1 0 0 0" type="mesh" contype="0" conaffinity="0" group="1" density="0" rgba="0.2 0.2 0.2 1" mesh="logo_link"/>
            <geom pos="0.0039635 0 -0.044" quat="1 0 0 0" type="mesh" rgba="0.2 0.2 0.2 1" mesh="logo_link"/>
            <geom pos="0.0039635 0 -0.044" type="mesh" contype="0" conaffinity="0" group="1" density="0" rgba="0.2 0.2 0.2 1" mesh="head_link"/>
            <geom pos="0.0039635 0 -0.044" type="mesh" rgba="0.2 0.2 0.2 1" mesh="head_link"/>
            <site name="imu_in_torso" size="0.01" pos="-0.03959 -0.00224 0.14792"/>

            <!-- ================= LEFT ARM/HAND ================= -->
            <!-- (unchanged geometry-chain; edits: palm site + finger joint damping/armature) -->
            <body name="left_shoulder_pitch_link" pos="0.0039563 0.10022 0.24778" quat="0.990264 0.139201 1.38722e-05 -9.86868e-05">
              <!-- ... upstream joints unchanged ... -->
              <body name="left_wrist_yaw_link" pos="0.046 0 0">
                <!-- ... wrist geoms ... -->
                <geom pos="0.0415 0.003 0" quat="1 0 0 0" type="mesh" contype="0" conaffinity="0" group="1" density="0" rgba="0.7 0.7 0.7 1" mesh="left_hand_palm_link"/>
                <geom pos="0.0415 0.003 0" quat="1 0 0 0" type="mesh" rgba="0.7 0.7 0.7 1" mesh="left_hand_palm_link"/>
                <!-- PALM SITE (left) -->
                <site name="palm_site_left" pos="0.0415 0.003 0" size="0.005" type="sphere" rgba="1 0.2 0.2 1"/>

                <!-- LEFT THUMB -->
                <body name="left_hand_thumb_0_link" pos="0.067 0.003 0">
                  <inertial pos="-0.000884246 -0.00863407 0.000944293" quat="0.462991 0.643965 -0.460173 0.398986" mass="0.0862366" diaginertia="1.6546e-05 1.60058e-05 1.43741e-05"/>
                  <joint name="left_hand_thumb_0_joint" pos="0 0 0" axis="0 1 0"
                         range="-1.0472 1.0472" actuatorfrcrange="-2.45 2.45"
                         damping="0.05" armature="0.002"/>
                  <!-- ... -->
                  <body name="left_hand_thumb_1_link" pos="-0.0025 -0.0193 0">
                    <joint name="left_hand_thumb_1_joint" pos="0 0 0" axis="0 0 1"
                           range="-0.724312 1.0472" actuatorfrcrange="-1.4 1.4"
                           damping="0.05" armature="0.002"/>
                    <!-- ... -->
                    <body name="left_hand_thumb_2_link" pos="0 -0.0458 0">
                      <joint name="left_hand_thumb_2_joint" pos="0 0 0" axis="0 0 1"
                             range="0 1.74533" actuatorfrcrange="-1.4 1.4"
                             damping="0.05" armature="0.002"/>
                      <!-- ... -->
                    </body>
                  </body>
                </body>

                <!-- LEFT MIDDLE -->
                <body name="left_hand_middle_0_link" pos="0.1192 0.0046 -0.0285">
                  <joint name="left_hand_middle_0_joint" pos="0 0 0" axis="0 0 1"
                         range="-1.5708 0" actuatorfrcrange="-1.4 1.4"
                         damping="0.05" armature="0.002"/>
                  <!-- ... -->
                  <body name="left_hand_middle_1_link" pos="0.0458 0 0">
                    <joint name="left_hand_middle_1_joint" pos="0 0 0" axis="0 0 1"
                           range="-1.74533 0" actuatorfrcrange="-1.4 1.4"
                           damping="0.05" armature="0.002"/>
                    <!-- ... -->
                  </body>
                </body>

                <!-- LEFT INDEX -->
                <body name="left_hand_index_0_link" pos="0.1192 0.0046 0.0285">
                  <joint name="left_hand_index_0_joint" pos="0 0 0" axis="0 0 1"
                         range="-1.5708 0" actuatorfrcrange="-1.4 1.4"
                         damping="0.05" armature="0.002"/>
                  <!-- ... -->
                  <body name="left_hand_index_1_link" pos="0.0458 0 0">
                    <joint name="left_hand_index_1_joint" pos="0 0 0" axis="0 0 1"
                           range="-1.74533 0" actuatorfrcrange="-1.4 1.4"
                           damping="0.05" armature="0.002"/>
                    <!-- ... -->
                  </body>
                </body>
              </body>
            </body>

            <!-- ================= RIGHT ARM/HAND ================= -->
            <body name="right_shoulder_pitch_link" pos="0.0039563 -0.10021 0.24778" quat="0.990264 -0.139201 1.38722e-05 9.86868e-05">
              <!-- ... upstream joints unchanged ... -->
              <body name="right_wrist_yaw_link" pos="0.046 0 0">
                <!-- ... wrist geoms ... -->
                <geom pos="0.0415 -0.003 0" quat="1 0 0 0" type="mesh" contype="0" conaffinity="0" group="1" density="0" rgba="0.7 0.7 0.7 1" mesh="right_hand_palm_link"/>
                <geom pos="0.0415 -0.003 0" quat="1 0 0 0" type="mesh" rgba="0.7 0.7 0.7 1" mesh="right_hand_palm_link"/>
                <!-- PALM SITE (right) -->
                <site name="palm_site_right" pos="0.0415 -0.003 0" size="0.005" type="sphere" rgba="1 0.2 0.2 1"/>

                <!-- RIGHT THUMB -->
                <body name="right_hand_thumb_0_link" pos="0.067 -0.003 0">
                  <joint name="right_hand_thumb_0_joint" pos="0 0 0" axis="0 1 0"
                         range="-1.0472 1.0472" actuatorfrcrange="-2.45 2.45"
                         damping="0.05" armature="0.002"/>
                  <!-- ... -->
                  <body name="right_hand_thumb_1_link" pos="-0.0025 0.0193 0">
                    <joint name="right_hand_thumb_1_joint" pos="0 0 0" axis="0 0 1"
                           range="-1.0472 0.724312" actuatorfrcrange="-1.4 1.4"
                           damping="0.05" armature="0.002"/>
                    <!-- ... -->
                    <body name="right_hand_thumb_2_link" pos="0 0.0458 0">
                      <joint name="right_hand_thumb_2_joint" pos="0 0 0" axis="0 0 1"
                             range="-1.74533 0" actuatorfrcrange="-1.4 1.4"
                             damping="0.05" armature="0.002"/>
                      <!-- ... -->
                    </body>
                  </body>
                </body>

                <!-- RIGHT MIDDLE -->
                <body name="right_hand_middle_0_link" pos="0.1192 -0.0046 -0.0285">
                  <joint name="right_hand_middle_0_joint" pos="0 0 0" axis="0 0 1"
                         range="0 1.5708" actuatorfrcrange="-1.4 1.4"
                         damping="0.05" armature="0.002"/>
                  <!-- ... -->
                  <body name="right_hand_middle_1_link" pos="0.0458 0 0">
                    <joint name="right_hand_middle_1_joint" pos="0 0 0" axis="0 0 1"
                           range="0 1.74533" actuatorfrcrange="-1.4 1.4"
                           damping="0.05" armature="0.002"/>
                    <!-- ... -->
                  </body>
                </body>

                <!-- RIGHT INDEX -->
                <body name="right_hand_index_0_link" pos="0.1192 -0.0046 0.0285">
                  <joint name="right_hand_index_0_joint" pos="0 0 0" axis="0 0 1"
                         range="0 1.5708" actuatorfrcrange="-1.4 1.4"
                         damping="0.05" armature="0.002"/>
                  <!-- ... -->
                  <body name="right_hand_index_1_link" pos="0.0458 0 0">
                    <joint name="right_hand_index_1_joint" pos="0 0 0" axis="0 0 1"
                           range="0 1.74533" actuatorfrcrange="-1.4 1.4"
                           damping="0.05" armature="0.002"/>
                    <!-- ... -->
                  </body>
                </body>
              </body>
            </body>

          </body>
        </body>
      </body>
    </body>
  </worldbody>

  <!-- Actuators unchanged -->
  <actuator>
    <motor name="left_hip_pitch_joint" joint="left_hip_pitch_joint"/>
    <motor name="left_hip_roll_joint" joint="left_hip_roll_joint"/>
    <motor name="left_hip_yaw_joint" joint="left_hip_yaw_joint"/>
    <motor name="left_knee_joint" joint="left_knee_joint"/>
    <motor name="left_ankle_pitch_joint" joint="left_ankle_pitch_joint"/>
    <motor name="left_ankle_roll_joint" joint="left_ankle_roll_joint"/>
    <motor name="right_hip_pitch_joint" joint="right_hip_pitch_joint"/>
    <motor name="right_hip_roll_joint" joint="right_hip_roll_joint"/>
    <motor name="right_hip_yaw_joint" joint="right_hip_yaw_joint"/>
    <motor name="right_knee_joint" joint="right_knee_joint"/>
    <motor name="right_ankle_pitch_joint" joint="right_ankle_pitch_joint"/>
    <motor name="right_ankle_roll_joint" joint="right_ankle_roll_joint"/>
    <motor name="waist_yaw_joint" joint="waist_yaw_joint"/>
    <motor name="waist_roll_joint" joint="waist_roll_joint"/>
    <motor name="waist_pitch_joint" joint="waist_pitch_joint"/>
    <motor name="left_shoulder_pitch_joint" joint="left_shoulder_pitch_joint"/>
    <motor name="left_shoulder_roll_joint" joint="left_shoulder_roll_joint"/>
    <motor name="left_shoulder_yaw_joint" joint="left_shoulder_yaw_joint"/>
    <motor name="left_elbow_joint" joint="left_elbow_joint"/>
    <motor name="left_wrist_roll_joint" joint="left_wrist_roll_joint"/>
    <motor name="left_wrist_pitch_joint" joint="left_wrist_pitch_joint"/>
    <motor name="left_wrist_yaw_joint" joint="left_wrist_yaw_joint"/>
    <motor name="left_hand_thumb_0_joint" joint="left_hand_thumb_0_joint"/>
    <motor name="left_hand_thumb_1_joint" joint="left_hand_thumb_1_joint"/>
    <motor name="left_hand_thumb_2_joint" joint="left_hand_thumb_2_joint"/>
    <motor name="left_hand_middle_0_joint" joint="left_hand_middle_0_joint"/>
    <motor name="left_hand_middle_1_joint" joint="left_hand_middle_1_joint"/>
    <motor name="left_hand_index_0_joint" joint="left_hand_index_0_joint"/>
    <motor name="left_hand_index_1_joint" joint="left_hand_index_1_joint"/>
    <motor name="right_shoulder_pitch_joint" joint="right_shoulder_pitch_joint"/>
    <motor name="right_shoulder_roll_joint" joint="right_shoulder_roll_joint"/>
    <motor name="right_shoulder_yaw_joint" joint="right_shoulder_yaw_joint"/>
    <motor name="right_elbow_joint" joint="right_elbow_joint"/>
    <motor name="right_wrist_roll_joint" joint="right_wrist_roll_joint"/>
    <motor name="right_wrist_pitch_joint" joint="right_wrist_pitch_joint"/>
    <motor name="right_wrist_yaw_joint" joint="right_wrist_yaw_joint"/>
    <motor name="right_hand_thumb_0_joint" joint="right_hand_thumb_0_joint"/>
    <motor name="right_hand_thumb_1_joint" joint="right_hand_thumb_1_joint"/>
    <motor name="right_hand_thumb_2_joint" joint="right_hand_thumb_2_joint"/>
    <motor name="right_hand_index_0_joint" joint="right_hand_index_0_joint"/>
    <motor name="right_hand_index_1_joint" joint="right_hand_index_1_joint"/>
    <motor name="right_hand_middle_0_joint" joint="right_hand_middle_0_joint"/>
    <motor name="right_hand_middle_1_joint" joint="right_hand_middle_1_joint"/>
  </actuator>

  <!-- IMU sensors unchanged -->
  <sensor>
    <gyro name="imu-torso-angular-velocity" site="imu_in_torso" noise="5e-4" cutoff="34.9"/>
    <accelerometer name="imu-torso-linear-acceleration" site="imu_in_torso" noise="1e-2" cutoff="157"/>
    <gyro name="imu-pelvis-angular-velocity" site="imu_in_pelvis" noise="5e-4" cutoff="34.9"/>
    <accelerometer name="imu-pelvis-linear-acceleration" site="imu_in_pelvis" noise="1e-2" cutoff="157"/>
  </sensor>
</mujoco>