<mujoco model="g1_29dof_with_hand_rev_1_0">
  <compiler angle="radian" meshdir="meshes"/>

  <!-- numerics -->
  <option timestep="0.002" integrator="Euler" cone="pyramidal"
          jacobian="dense" iterations="80" tolerance="1e-9"/>

  <!-- meshes -->
  <asset>
    <mesh name="pelvis" file="pelvis.STL"/>
    <mesh name="pelvis_contour_link" file="pelvis_contour_link.STL"/>
    <mesh name="left_hip_pitch_link" file="left_hip_pitch_link.STL"/>
    <mesh name="left_hip_roll_link" file="left_hip_roll_link.STL"/>
    <mesh name="left_hip_yaw_link" file="left_hip_yaw_link.STL"/>
    <mesh name="left_knee_link" file="left_knee_link.STL"/>
    <mesh name="left_ankle_pitch_link" file="left_ankle_pitch_link.STL"/>
    <mesh name="left_ankle_roll_link" file="left_ankle_roll_link.STL"/>
    <mesh name="right_hip_pitch_link" file="right_hip_pitch_link.STL"/>
    <mesh name="right_hip_roll_link" file="right_hip_roll_link.STL"/>
    <mesh name="right_hip_yaw_link" file="right_hip_yaw_link.STL"/>
    <mesh name="right_knee_link" file="right_knee_link.STL"/>
    <mesh name="right_ankle_pitch_link" file="right_ankle_pitch_link.STL"/>
    <mesh name="right_ankle_roll_link" file="right_ankle_roll_link.STL"/>
    <mesh name="waist_yaw_link" file="waist_yaw_link_rev_1_0.STL"/>
    <mesh name="waist_roll_link" file="waist_roll_link_rev_1_0.STL"/>
    <mesh name="torso_link" file="torso_link_rev_1_0.STL"/>
    <mesh name="logo_link" file="logo_link.STL"/>
    <mesh name="head_link" file="head_link.STL"/>

    <mesh name="left_shoulder_pitch_link" file="left_shoulder_pitch_link.STL"/>
    <mesh name="left_shoulder_roll_link" file="left_shoulder_roll_link.STL"/>
    <mesh name="left_shoulder_yaw_link" file="left_shoulder_yaw_link.STL"/>
    <mesh name="left_elbow_link" file="left_elbow_link.STL"/>
    <mesh name="left_wrist_roll_link" file="left_wrist_roll_link.STL"/>
    <mesh name="left_wrist_pitch_link" file="left_wrist_pitch_link.STL"/>
    <mesh name="left_wrist_yaw_link" file="left_wrist_yaw_link.STL"/>

    <mesh name="right_shoulder_pitch_link" file="right_shoulder_pitch_link.STL"/>
    <mesh name="right_shoulder_roll_link" file="right_shoulder_roll_link.STL"/>
    <mesh name="right_shoulder_yaw_link" file="right_shoulder_yaw_link.STL"/>
    <mesh name="right_elbow_link" file="right_elbow_link.STL"/>
    <mesh name="right_wrist_roll_link" file="right_wrist_roll_link.STL"/>
    <mesh name="right_wrist_pitch_link" file="right_wrist_pitch_link.STL"/>
    <mesh name="right_wrist_yaw_link" file="right_wrist_yaw_link.STL"/>
  </asset>

    <!-- H1 finger visuals (placeholders) -->
  <asset>
    <mesh name="h1_hand_base"          file="L_hand_base_link.STL"/>
    <mesh name="h1_index_proximal"     file="L_index_proximal.STL"/>
    <mesh name="h1_index_intermediate" file="L_index_intermediate.STL"/>
    <mesh name="h1_middle_proximal"    file="L_middle_proximal.STL"/>
    <mesh name="h1_middle_intermediate"file="L_middle_intermediate.STL"/>
    <mesh name="h1_ring_proximal"      file="L_ring_proximal.STL"/>
    <mesh name="h1_ring_intermediate"  file="L_ring_intermediate.STL"/>
    <mesh name="h1_pinky_proximal"     file="L_pinky_proximal.STL"/>
    <mesh name="h1_pinky_intermediate" file="L_pinky_intermediate.STL"/>
    <mesh name="h1_thumb_prox_base"    file="L_thumb_proximal_base.STL"/>
    <mesh name="h1_thumb_proximal"     file="L_thumb_proximal.STL"/>
    <mesh name="h1_thumb_intermediate" file="L_thumb_intermediate.STL"/>
    <mesh name="h1_thumb_distal"       file="L_thumb_distal.STL"/>
  </asset>

  <statistic center="1.0 0.7 1.0" extent="0.8"/>
  <visual>
    <headlight diffuse="0.6 0.6 0.6" ambient="0.1 0.1 0.1" specular="0.9 0.9 0.9"/>
    <rgba haze="0.15 0.25 0.35 1"/>
    <global azimuth="-140" elevation="-20"/>
  </visual>
  <asset>
    <texture type="skybox" builtin="flat" rgb1="0 0 0" rgb2="0 0 0" width="512" height="3072"/>
    <texture type="2d" name="groundplane" builtin="checker" mark="edge"
             rgb1="0.2 0.3 0.4" rgb2="0.1 0.2 0.3" markrgb="0.8 0.8 0.8"
             width="300" height="300"/>
    <material name="groundplane" texture="groundplane" texuniform="true" texrepeat="5 5" reflectance="0.2"/>
  </asset>

  <worldbody>
    <light pos="1 0 3.5" dir="0 0 -1" directional="true"/>
    <geom name="floor" size="0 0 0.05" type="plane" material="groundplane"/>
    <body name="world_anchor"/>

    <!-- can + required site -->
    <body name="can_body" pos="0.42 -0.03 1.03">
      <geom name="can_geom" type="cylinder" size="0.03 0.06"
            rgba="0.9 0.6 0.2 1" friction="1.0 0.005 0.0001"
            contype="1" conaffinity="1"/>
      <site name="can_site" pos="0 0 0" size="0.005" type="sphere" rgba="0.2 0.8 0.2 1"/>
      <!-- <joint name="can_free" type="free"/> -->
    </body>

    <!-- ================= BASE & TORSO ================= -->
    <body name="pelvis" pos="0 0 0.793">
      <inertial pos="0 0 -0.07605" quat="1 0 -0.000399148 0" mass="3.813"
                diaginertia="0.010549 0.0093089 0.0079184"/>
      <!-- visuals only -->
      <geom type="mesh" contype="0" conaffinity="0" group="1" density="0" rgba="0.2 0.2 0.2 1" mesh="pelvis"/>
      <geom type="mesh" contype="0" conaffinity="0" group="1" density="0" rgba="0.7 0.7 0.7 1" mesh="pelvis_contour_link"/>
      <geom type="mesh" rgba="0.7 0.7 0.7 1" mesh="pelvis_contour_link"/>
      <site name="imu_in_pelvis" size="0.01" pos="0.04525 0 -0.08339"/>

      <!-- lap collision (bit 1) -->
      <geom name="lap_collision" type="box" size="0.10 0.12 0.08"
            pos="-0.02 0.00 -0.04" rgba="0.1 0.3 0.8 0.05"
            density="0" contype="1" conaffinity="1" margin="0.002"/>

      <!-- legs omitted (locked in your original) -->

      <body name="waist_yaw_link">
        <inertial pos="0.003494 0.000233 0.018034" quat="0.289697 0.591001 -0.337795 0.672821" mass="0.214" diaginertia="0.000163531 0.000107714 0.000102205"/>
        <joint name="waist_yaw_joint" pos="0 0 0" axis="0 0 1" range="0 0" damping="50"/>
        <geom type="mesh" contype="0" conaffinity="0" group="1" density="0" rgba="0.7 0.7 0.7 1" mesh="waist_yaw_link"/>
        <body name="waist_roll_link" pos="-0.0039635 0 0.044">
          <inertial pos="0 2.3e-05 0" quat="0.5 0.5 -0.5 0.5" mass="0.086" diaginertia="8.245e-06 7.079e-06 6.339e-06"/>
          <joint name="waist_roll_joint" pos="0 0 0" axis="1 0 0" range="0 0" damping="50"/>
          <geom type="mesh" contype="0" conaffinity="0" group="1" density="0" rgba="0.7 0.7 0.7 1" mesh="waist_roll_link"/>
          <body name="torso_link">
            <inertial pos="0.00203158 0.000339683 0.184568" quat="0.999803 -6.03319e-05 0.0198256 0.00131986" mass="7.818" diaginertia="0.121847 0.109825 0.0273735"/>
            <joint name="waist_pitch_joint" pos="0 0 0" axis="0 1 0" range="0 0" damping="50"/>
            <geom type="mesh" contype="0" conaffinity="0" group="1" density="0" rgba="0.7 0.7 0.7 1" mesh="torso_link"/>
            <geom type="mesh" rgba="0.7 0.7 0.7 1" mesh="torso_link"/>
            <geom pos="0.0039635 0 -0.044" quat="1 0 0 0" type="mesh" contype="0" conaffinity="0" group="1" density="0" rgba="0.2 0.2 0.2 1" mesh="logo_link"/>
            <geom pos="0.0039635 0 -0.044" type="mesh" contype="0" conaffinity="0" group="1" density="0" rgba="0.2 0.2 0.2 1" mesh="head_link"/>
            <site name="imu_in_torso" size="0.01" pos="-0.03959 -0.00224 0.14792"/>

            <!-- torso collision: now bit 1 (collides with arms/hands) -->
            <geom name="torso_collision" type="box" size="0.10 0.12 0.14"
                  pos="0.10 0.00 0.12" rgba="0.1 0.7 0.1 0.05"
                  density="0" contype="1" conaffinity="1" margin="0.002"/>

            <!-- ================= LEFT ARM ================= -->
            <body name="left_shoulder_pitch_link" pos="0.0039563 0.10022 0.24778" quat="0.990264 0.139201 0 0">
              <inertial pos="0 0.035892 -0.011628" quat="0.654152 0.0130458 -0.326267 0.68225" mass="0.718" diaginertia="0.000465864 0.000432842 0.000406394"/>
              <joint name="left_shoulder_pitch_joint" pos="0 0 0" axis="0 1 0" range="-3.0892 2.6704" damping="8"/>
              <geom type="mesh" contype="0" conaffinity="0" group="1" density="0" rgba="0.7 0.7 0.7 1" mesh="left_shoulder_pitch_link"/>
              <body name="left_shoulder_roll_link" pos="0 0.038 -0.013831" quat="0.990268 -0.139172 0 0">
                <inertial pos="-0.000227 0.00727 -0.063243" quat="0.701256 -0.0196223 -0.00710317 0.712604" mass="0.643" diaginertia="0.000691311 0.000618011 0.000388977"/>
                <joint name="left_shoulder_roll_joint" pos="0 0 0" axis="1 0 0" range="-1.5882 2.2515" damping="8"/>
                <geom type="mesh" contype="0" conaffinity="0" group="1" density="0" rgba="0.7 0.7 0.7 1" mesh="left_shoulder_roll_link"/>
                <body name="left_shoulder_yaw_link" pos="0 0.00624 -0.1032">
                  <inertial pos="0.010773 -0.002949 -0.072009" quat="0.716879 -0.0964829 -0.0679942 0.687134" mass="0.734" diaginertia="0.00106187 0.00103217 0.000400661"/>
                  <joint name="left_shoulder_yaw_joint" pos="0 0 0" axis="0 0 1" range="-2.618 2.618" damping="8"/>
                  <geom type="mesh" contype="0" conaffinity="0" group="1" density="0" rgba="0.7 0.7 0.7 1" mesh="left_shoulder_yaw_link"/>

                  <!-- Left upper-arm collision capsule (bit 1) -->
                  <geom name="left_upperarm_col" type="capsule"
                        fromto="0.02 0 -0.02   0.02 0 -0.20" size="0.03"
                        rgba="0 0.5 1 0.05" contype="1" conaffinity="1"
                        friction="0.8 0.01 0.0001" margin="0.002"/>

                  <body name="left_elbow_link" pos="0.015783 0 -0.080518">
                    <inertial pos="0.064956 0.004454 -0.010062" quat="0.541765 0.636132 0.388821 0.388129" mass="0.6" diaginertia="0.000443035 0.000421612 0.000259353"/>
                    <joint name="left_elbow_joint" pos="0 0 0" axis="0 1 0" range="-1.0472 2.0944" damping="8"/>
                    <geom type="mesh" contype="0" conaffinity="0" group="1" density="0" rgba="0.7 0.7 0.7 1" mesh="left_elbow_link"/>

                    <!-- Left forearm collision capsule (bit 1) -->
                    <geom name="left_forearm_col" type="capsule"
                          fromto="0.02 0 0   0.14 0 -0.01" size="0.025"
                          rgba="0 0.5 1 0.05" contype="1" conaffinity="1"
                          friction="0.8 0.01 0.0001" margin="0.002"/>

                    <body name="left_wrist_roll_link" pos="0.1 0.00188791 -0.01">
                      <inertial pos="0.0171394 0.000537591 0" quat="0.575338 0.411667 -0.574906 0.411094" mass="0.085445" diaginertia="5.48211e-05 4.96646e-05 3.57798e-05"/>
                      <joint name="left_wrist_roll_joint" pos="0 0 0" axis="1 0 0" range="-1.97222 1.97222" damping="6"/>
                      <geom type="mesh" contype="0" conaffinity="0" group="1" density="0" rgba="0.7 0.7 0.7 1" mesh="left_wrist_roll_link"/>
                      <body name="left_wrist_pitch_link" pos="0.038 0 0">
                        <inertial pos="0.0229999 -0.00111685 -0.00111658" quat="0.249998 0.661363 0.293036 0.643608" mass="0.48405" diaginertia="0.000430353 0.000429873 0.000164648"/>
                        <joint name="left_wrist_pitch_joint" pos="0 0 0" axis="0 1 0" range="-1.61443 1.61443" damping="6"/>
                        <geom type="mesh" contype="0" conaffinity="0" group="1" density="0" rgba="0.7 0.7 0.7 1" mesh="left_wrist_pitch_link"/>
                        <body name="left_wrist_yaw_link" pos="0.046 0 0">
                          <inertial pos="0.0885506 0.00212216 -0.000374562" quat="0.487149 0.493844 0.513241 0.505358" mass="0.457415" diaginertia="0.00105989 0.000895419 0.000323842"/>
                          <joint name="left_wrist_yaw_joint" pos="0 0 0" axis="0 0 1" range="-1.61443 1.61443" damping="6"/>
                          <geom type="mesh" contype="0" conaffinity="0" group="1" density="0" rgba="0.7 0.7 0.7 1" mesh="left_wrist_yaw_link"/>

                          <!-- LEFT PALM collision (bit 1) -->
                          <!-- LEFT: Inspire FTX hand (12-DOF) with H1 visual meshes -->
                          <geom name="left_palm_collision" type="box" size="0.03 0.025 0.008"
                                pos="0.07 0 0" mass="0.15" friction="1.0 0.01 0.0001"
                                contype="1" conaffinity="1" solimp="0.95 0.99 0.001" solref="0.005 1"/>
                          <!-- optional palm visual -->
                          <geom type="mesh" mesh="h1_hand_base" pos="0.07 0 0"
                                rgba="0.8 0.8 0.8 1" contype="0" conaffinity="0" density="0"/>
                          <site name="palm_site_left" pos="0.07 0 0" size="0.005" type="sphere" rgba="1 0.2 0.2 1"/>

                          <!-- Thumb: ab/adduction + 3x flex -->
                          <!-- LEFT THUMB -->
                          <body name="left_thumb_base" pos="0.055 0.025 0.0">
                            <!-- NEW: give this body a small mass so its joint is valid -->
                            <inertial mass="0.005" pos="0 0 0" diaginertia="1e-6 1e-6 1e-6"/>
                            <joint name="left_hand_thumb_0_joint" axis="0 1 0" range="-0.8 0.8"  damping="0.05" armature="0.002" stiffness="0"/>
                            <body name="left_thumb_cmc" pos="0 0 0">
                              <joint name="left_hand_thumb_1_joint" axis="0 0 1" range="0 1.2"    damping="0.05" armature="0.002" stiffness="0"/>
                              <geom  type="capsule" fromto="0 0 0  0.035 0 0" size="0.008" rgba="0.8 0.8 0.8 1"
                                    density="800" friction="2.0 0.01 0.001" contype="1" conaffinity="1" solimp="0.95 0.99 0.001" solref="0.005 1"/>
                              <geom  type="mesh" mesh="h1_thumb_prox_base" pos="0.0175 0 0" rgba="0.9 0.9 0.9 1"
                                    contype="0" conaffinity="0" density="0"/>
                              <body name="left_thumb_mcp" pos="0.035 0 0">
                                <joint name="left_hand_thumb_2_joint" axis="0 0 1" range="0 1.2"  damping="0.05" armature="0.002" stiffness="0"/>
                                <geom  type="capsule" fromto="0 0 0  0.03 0 0"  size="0.008" rgba="0.8 0.8 0.8 1"
                                      density="800" friction="2.0 0.01 0.001" contype="1" conaffinity="1" solimp="0.95 0.99 0.001" solref="0.005 1"/>
                                <geom  type="mesh" mesh="h1_thumb_proximal" pos="0.015 0 0" rgba="0.9 0.9 0.9 1"
                                      contype="0" conaffinity="0" density="0"/>
                                <body name="left_thumb_ip" pos="0.03 0 0">
                                  <joint name="left_hand_thumb_3_joint" axis="0 0 1" range="0 1.2" damping="0.05" armature="0.002" stiffness="0"/>
                                  <geom  type="capsule" fromto="0 0 0  0.028 0 0" size="0.0075" rgba="0.8 0.8 0.8 1"
                                        density="800" friction="2.0 0.01 0.001" contype="1" conaffinity="1" solimp="0.95 0.99 0.001" solref="0.005 1"/>
                                  <geom  type="mesh" mesh="h1_thumb_intermediate" pos="0.014 0 0" rgba="0.9 0.9 0.9 1"
                                        contype="0" conaffinity="0" density="0"/>
                                  <site name="left_thumb_tip" pos="0.028 0 0" size="0.004" type="sphere" rgba="0.2 0.8 0.2 1"/>
                                  <geom  type="mesh" mesh="h1_thumb_distal" pos="0.022 0 0" rgba="0.9 0.9 0.9 1"
                                        contype="0" conaffinity="0" density="0"/>
                                </body>
                              </body>
                            </body>
                          </body>

                          <!-- Index (2 DOF) -->
                          <body name="left_index_base" pos="0.075 0.02 0.0">
                            <joint name="left_hand_index_0_joint" axis="0 0 1" range="0 1.4" damping="0.05" armature="0.002" stiffness="0"/>
                            <geom  type="capsule" fromto="0 0 0  0.04 0 0" size="0.008" rgba="0.8 0.8 0.8 1"
                                  density="800" friction="2.0 0.01 0.001" contype="1" conaffinity="1" solimp="0.95 0.99 0.001" solref="0.005 1"/>
                            <geom  type="mesh" mesh="h1_index_proximal" pos="0.02 0 0" rgba="0.9 0.9 0.9 1"
                                  contype="0" conaffinity="0" density="0"/>
                            <body name="left_index_mid" pos="0.04 0 0">
                              <joint name="left_hand_index_1_joint" axis="0 0 1" range="0 1.4" damping="0.05" armature="0.002" stiffness="0"/>
                              <geom  type="capsule" fromto="0 0 0  0.03 0 0" size="0.0075" rgba="0.8 0.8 0.8 1"
                                    density="800" friction="2.0 0.01 0.001" contype="1" conaffinity="1" solimp="0.95 0.99 0.001" solref="0.005 1"/>
                              <geom  type="mesh" mesh="h1_index_intermediate" pos="0.015 0 0" rgba="0.9 0.9 0.9 1"
                                    contype="0" conaffinity="0" density="0"/>
                              <site name="left_index_tip" pos="0.03 0 0" size="0.004" type="sphere" rgba="0.2 0.8 0.2 1"/>
                            </body>
                          </body>

                          <!-- Middle (2 DOF) -->
                          <body name="left_middle_base" pos="0.075 0.006 0.0">
                            <joint name="left_hand_middle_0_joint" axis="0 0 1" range="0 1.4" damping="0.05" armature="0.002" stiffness="0"/>
                            <geom  type="capsule" fromto="0 0 0  0.042 0 0" size="0.008" rgba="0.8 0.8 0.8 1"
                                  density="800" friction="2.0 0.01 0.001" contype="1" conaffinity="1" solimp="0.95 0.99 0.001" solref="0.005 1"/>
                            <geom  type="mesh" mesh="h1_middle_proximal" pos="0.021 0 0" rgba="0.9 0.9 0.9 1"
                                  contype="0" conaffinity="0" density="0"/>
                            <body name="left_middle_mid" pos="0.042 0 0">
                              <joint name="left_hand_middle_1_joint" axis="0 0 1" range="0 1.4" damping="0.05" armature="0.002" stiffness="0"/>
                              <geom  type="capsule" fromto="0 0 0  0.032 0 0" size="0.0075" rgba="0.8 0.8 0.8 1"
                                    density="800" friction="2.0 0.01 0.001" contype="1" conaffinity="1" solimp="0.95 0.99 0.001" solref="0.005 1"/>
                              <geom  type="mesh" mesh="h1_middle_intermediate" pos="0.016 0 0" rgba="0.9 0.9 0.9 1"
                                    contype="0" conaffinity="0" density="0"/>
                              <site name="left_middle_tip" pos="0.032 0 0" size="0.004" type="sphere" rgba="0.2 0.8 0.2 1"/>
                            </body>
                          </body>

                          <!-- Ring (2 DOF) -->
                          <body name="left_ring_base" pos="0.075 -0.008 0.0">
                            <joint name="left_hand_ring_0_joint" axis="0 0 1" range="0 1.4" damping="0.05" armature="0.002" stiffness="0"/>
                            <geom  type="capsule" fromto="0 0 0  0.04 0 0" size="0.008" rgba="0.8 0.8 0.8 1"
                                  density="800" friction="2.0 0.01 0.001" contype="1" conaffinity="1" solimp="0.95 0.99 0.001" solref="0.005 1"/>
                            <geom  type="mesh" mesh="h1_ring_proximal" pos="0.02 0 0" rgba="0.9 0.9 0.9 1"
                                  contype="0" conaffinity="0" density="0"/>
                            <body name="left_ring_mid" pos="0.04 0 0">
                              <joint name="left_hand_ring_1_joint" axis="0 0 1" range="0 1.4" damping="0.05" armature="0.002" stiffness="0"/>
                              <geom  type="capsule" fromto="0 0 0  0.03 0 0" size="0.0075" rgba="0.8 0.8 0.8 1"
                                    density="800" friction="2.0 0.01 0.001" contype="1" conaffinity="1" solimp="0.95 0.99 0.001" solref="0.005 1"/>
                              <geom  type="mesh" mesh="h1_ring_intermediate" pos="0.015 0 0" rgba="0.9 0.9 0.9 1"
                                    contype="0" conaffinity="0" density="0"/>
                              <site name="left_ring_tip" pos="0.03 0 0" size="0.004" type="sphere" rgba="0.2 0.8 0.2 1"/>
                            </body>
                          </body>

                          <!-- Pinky (2 DOF) -->
                          <body name="left_pinky_base" pos="0.075 -0.022 0.0">
                            <joint name="left_hand_pinky_0_joint" axis="0 0 1" range="0 1.4" damping="0.05" armature="0.002" stiffness="0"/>
                            <geom  type="capsule" fromto="0 0 0  0.035 0 0" size="0.0075" rgba="0.8 0.8 0.8 1"
                                  density="800" friction="2.0 0.01 0.001" contype="1" conaffinity="1" solimp="0.95 0.99 0.001" solref="0.005 1"/>
                            <geom  type="mesh" mesh="h1_pinky_proximal" pos="0.017 0 0" rgba="0.9 0.9 0.9 1"
                                  contype="0" conaffinity="0" density="0"/>
                            <body name="left_pinky_mid" pos="0.035 0 0">
                              <joint name="left_hand_pinky_1_joint" axis="0 0 1" range="0 1.4" damping="0.05" armature="0.002" stiffness="0"/>
                              <geom  type="capsule" fromto="0 0 0  0.028 0 0" size="0.007" rgba="0.8 0.8 0.8 1"
                                    density="800" friction="2.0 0.01 0.001" contype="1" conaffinity="1" solimp="0.95 0.99 0.001" solref="0.005 1"/>
                              <geom  type="mesh" mesh="h1_pinky_intermediate" pos="0.014 0 0" rgba="0.9 0.9 0.9 1"
                                    contype="0" conaffinity="0" density="0"/>
                              <site name="left_pinky_tip" pos="0.028 0 0" size="0.004" type="sphere" rgba="0.2 0.8 0.2 1"/>
                            </body>
                          </body>
                          <!-- ========= END LEFT HAND ========= -->
                        </body>
                      </body>
                    </body>
                  </body>
                </body>
              </body>
            </body>

            <!-- ================= RIGHT ARM ================= -->
            <body name="right_shoulder_pitch_link" pos="0.0039563 -0.10021 0.24778" quat="0.990264 -0.139201 0 0">
              <inertial pos="0 -0.035892 -0.011628" quat="0.68225 -0.326267 0.0130458 0.654152" mass="0.718" diaginertia="0.000465864 0.000432842 0.000406394"/>
              <joint name="right_shoulder_pitch_joint" pos="0 0 0" axis="0 1 0" range="-3.0892 2.6704" damping="8"/>
              <geom type="mesh" contype="0" conaffinity="0" group="1" density="0" rgba="0.7 0.7 0.7 1" mesh="right_shoulder_pitch_link"/>
              <body name="right_shoulder_roll_link" pos="0 -0.038 -0.013831" quat="0.990268 0.139172 0 0">
                <inertial pos="-0.000227 -0.00727 -0.063243" quat="0.712604 -0.00710317 -0.0196223 0.701256" mass="0.643" diaginertia="0.000691311 0.000618011 0.000388977"/>
                <joint name="right_shoulder_roll_joint" pos="0 0 0" axis="1 0 0" range="-2.2515 1.5882" damping="8"/>
                <geom type="mesh" contype="0" conaffinity="0" group="1" density="0" rgba="0.7 0.7 0.7 1" mesh="right_shoulder_roll_link"/>
                <body name="right_shoulder_yaw_link" pos="0 -0.00624 -0.1032">
                  <inertial pos="0.010773 0.002949 -0.072009" quat="0.687134 -0.0679942 -0.0964829 0.716879" mass="0.734" diaginertia="0.00106187 0.00103217 0.000400661"/>
                  <joint name="right_shoulder_yaw_joint" pos="0 0 0" axis="0 0 1" range="-2.618 2.618" damping="8"/>
                  <geom type="mesh" contype="0" conaffinity="0" group="1" density="0" rgba="0.7 0.7 0.7 1" mesh="right_shoulder_yaw_link"/>

                  <!-- Right upper-arm collision -->
                  <geom name="right_upperarm_col" type="capsule"
                        fromto="0.02 0 -0.02   0.02 0 -0.20" size="0.03"
                        rgba="0 0.5 1 0.05" contype="1" conaffinity="1"
                        friction="0.8 0.01 0.0001" margin="0.002"/>

                  <body name="right_elbow_link" pos="0.015783 0 -0.080518">
                    <inertial pos="0.064956 -0.004454 -0.010062" quat="0.388129 0.388821 0.636132 0.541765" mass="0.6" diaginertia="0.000443035 0.000421612 0.000259353"/>
                    <joint name="right_elbow_joint" pos="0 0 0" axis="0 1 0" range="-1.0472 2.0944" damping="8"/>
                    <geom type="mesh" contype="0" conaffinity="0" group="1" density="0" rgba="0.7 0.7 0.7 1" mesh="right_elbow_link"/>

                    <!-- Right forearm collision -->
                    <geom name="right_forearm_col" type="capsule"
                          fromto="0.02 0 0   0.14 0 -0.01" size="0.025"
                          rgba="0 0.5 1 0.05" contype="1" conaffinity="1"
                          friction="0.8 0.01 0.0001" margin="0.002"/>

                    <body name="right_wrist_roll_link" pos="0.1 -0.00188791 -0.01">
                      <inertial pos="0.0171394 -0.000537591 0" quat="0.411667 0.575338 -0.411094 0.574906" mass="0.085445" diaginertia="5.48211e-05 4.96646e-05 3.57798e-05"/>
                      <joint name="right_wrist_roll_joint" pos="0 0 0" axis="1 0 0" range="-1.97222 1.97222" damping="6"/>
                      <geom type="mesh" contype="0" conaffinity="0" group="1" density="0" rgba="0.7 0.7 0.7 1" mesh="right_wrist_roll_link"/>
                      <body name="right_wrist_pitch_link" pos="0.038 0 0">
                        <inertial pos="0.0229999 0.00111685 -0.00111658" quat="0.643608 0.293036 0.661363 0.249998" mass="0.48405" diaginertia="0.000430353 0.000429873 0.000164648"/>
                        <joint name="right_wrist_pitch_joint" pos="0 0 0" axis="0 1 0" range="-1.61443 1.61443" damping="6"/>
                        <geom type="mesh" contype="0" conaffinity="0" group="1" density="0" rgba="0.7 0.7 0.7 1" mesh="right_wrist_pitch_link"/>
                        <body name="right_wrist_yaw_link" pos="0.046 0 0">
                          <inertial pos="0.0885506 -0.00212216 -0.000374562" quat="0.505358 0.513241 0.493844 0.487149" mass="0.457415" diaginertia="0.00105989 0.000895419 0.000323842"/>
                          <joint name="right_wrist_yaw_joint" pos="0 0 0" axis="0 0 1" range="-1.61443 1.61443" damping="6"/>
                          <geom type="mesh" contype="0" conaffinity="0" group="1" density="0" rgba="0.7 0.7 0.7 1" mesh="right_wrist_yaw_link"/>

                          <!-- RIGHT PALM collision (bit 1) -->
                          <!-- RIGHT: Inspire FTX hand (12-DOF) with H1 visual meshes -->
                          <geom name="right_palm_collision" type="box" size="0.03 0.025 0.008"
                                pos="0.07 0 0" mass="0.15" friction="1.0 0.01 0.0001"
                                contype="1" conaffinity="1" solimp="0.95 0.99 0.001" solref="0.005 1"/>
                          <geom type="mesh" mesh="h1_hand_base" pos="0.07 0 0"
                                rgba="0.8 0.8 0.8 1" contype="0" conaffinity="0" density="0"/>
                          <site name="palm_site_right" pos="0.07 0 0" size="0.005" type="sphere" rgba="1 0.2 0.2 1"/>

                          <!-- Thumb: axes flipped on right hand -->
                          <!-- RIGHT THUMB -->
                          <body name="right_thumb_base" pos="0.055 -0.025 0.0">
                            <!-- NEW: give this body a small mass so its joint is valid -->
                            <inertial mass="0.005" pos="0 0 0" diaginertia="1e-6 1e-6 1e-6"/>
                            <joint name="right_hand_thumb_0_joint" axis="0 -1 0" range="-0.8 0.8" damping="0.05" armature="0.002" stiffness="0"/>
                            <body name="right_thumb_cmc" pos="0 0 0">
                              <joint name="right_hand_thumb_1_joint" axis="0 0 -1" range="0 1.2"  damping="0.05" armature="0.002" stiffness="0"/>
                              <geom  type="capsule" fromto="0 0 0  0.035 0 0" size="0.008" rgba="0.8 0.8 0.8 1"
                                    density="800" friction="2.0 0.01 0.001" contype="1" conaffinity="1" solimp="0.95 0.99 0.001" solref="0.005 1"/>
                              <geom  type="mesh" mesh="h1_thumb_prox_base" pos="0.0175 0 0" rgba="0.9 0.9 0.9 1"
                                    contype="0" conaffinity="0" density="0"/>
                              <body name="right_thumb_mcp" pos="0.035 0 0">
                                <joint name="right_hand_thumb_2_joint" axis="0 0 -1" range="0 1.2" damping="0.05" armature="0.002" stiffness="0"/>
                                <geom  type="capsule" fromto="0 0 0  0.03 0 0"  size="0.008" rgba="0.8 0.8 0.8 1"
                                      density="800" friction="2.0 0.01 0.001" contype="1" conaffinity="1" solimp="0.95 0.99 0.001" solref="0.005 1"/>
                                <geom  type="mesh" mesh="h1_thumb_proximal" pos="0.015 0 0" rgba="0.9 0.9 0.9 1"
                                      contype="0" conaffinity="0" density="0"/>
                                <body name="right_thumb_ip" pos="0.03 0 0">
                                  <joint name="right_hand_thumb_3_joint" axis="0 0 -1" range="0 1.2" damping="0.05" armature="0.002" stiffness="0"/>
                                  <geom  type="capsule" fromto="0 0 0  0.028 0 0" size="0.0075" rgba="0.8 0.8 0.8 1"
                                        density="800" friction="2.0 0.01 0.001" contype="1" conaffinity="1" solimp="0.95 0.99 0.001" solref="0.005 1"/>
                                  <geom  type="mesh" mesh="h1_thumb_intermediate" pos="0.014 0 0" rgba="0.9 0.9 0.9 1"
                                        contype="0" conaffinity="0" density="0"/>
                                  <site name="right_thumb_tip" pos="0.028 0 0" size="0.004" type="sphere" rgba="0.2 0.8 0.2 1"/>
                                  <geom  type="mesh" mesh="h1_thumb_distal" pos="0.022 0 0" rgba="0.9 0.9 0.9 1"
                                        contype="0" conaffinity="0" density="0"/>
                                </body>
                              </body>
                            </body>
                          </body>

                          <!-- Index (2 DOF) -->
                          <body name="right_index_base" pos="0.075 -0.02 0.0">
                            <joint name="right_hand_index_0_joint" axis="0 0 1" range="0 1.4" damping="0.05" armature="0.002" stiffness="0"/>
                            <geom  type="capsule" fromto="0 0 0  0.04 0 0" size="0.008" rgba="0.8 0.8 0.8 1"
                                  density="800" friction="2.0 0.01 0.001" contype="1" conaffinity="1" solimp="0.95 0.99 0.001" solref="0.005 1"/>
                            <geom  type="mesh" mesh="h1_index_proximal" pos="0.02 0 0" rgba="0.9 0.9 0.9 1"
                                  contype="0" conaffinity="0" density="0"/>
                            <body name="right_index_mid" pos="0.04 0 0">
                              <joint name="right_hand_index_1_joint" axis="0 0 1" range="0 1.4" damping="0.05" armature="0.002" stiffness="0"/>
                              <geom  type="capsule" fromto="0 0 0  0.03 0 0" size="0.0075" rgba="0.8 0.8 0.8 1"
                                    density="800" friction="2.0 0.01 0.001" contype="1" conaffinity="1" solimp="0.95 0.99 0.001" solref="0.005 1"/>
                              <geom  type="mesh" mesh="h1_index_intermediate" pos="0.015 0 0" rgba="0.9 0.9 0.9 1"
                                    contype="0" conaffinity="0" density="0"/>
                              <site name="right_index_tip" pos="0.03 0 0" size="0.004" type="sphere" rgba="0.2 0.8 0.2 1"/>
                            </body>
                          </body>

                          <!-- Middle (2 DOF) -->
                          <body name="right_middle_base" pos="0.075 -0.006 0.0">
                            <joint name="right_hand_middle_0_joint" axis="0 0 1" range="0 1.4" damping="0.05" armature="0.002" stiffness="0"/>
                            <geom  type="capsule" fromto="0 0 0  0.042 0 0" size="0.008" rgba="0.8 0.8 0.8 1"
                                  density="800" friction="2.0 0.01 0.001" contype="1" conaffinity="1" solimp="0.95 0.99 0.001" solref="0.005 1"/>
                            <geom  type="mesh" mesh="h1_middle_proximal" pos="0.021 0 0" rgba="0.9 0.9 0.9 1"
                                  contype="0" conaffinity="0" density="0"/>
                            <body name="right_middle_mid" pos="0.042 0 0">
                              <joint name="right_hand_middle_1_joint" axis="0 0 1" range="0 1.4" damping="0.05" armature="0.002" stiffness="0"/>
                              <geom  type="capsule" fromto="0 0 0  0.032 0 0" size="0.0075" rgba="0.8 0.8 0.8 1"
                                    density="800" friction="2.0 0.01 0.001" contype="1" conaffinity="1" solimp="0.95 0.99 0.001" solref="0.005 1"/>
                              <geom  type="mesh" mesh="h1_middle_intermediate" pos="0.016 0 0" rgba="0.9 0.9 0.9 1"
                                    contype="0" conaffinity="0" density="0"/>
                              <site name="right_middle_tip" pos="0.032 0 0" size="0.004" type="sphere" rgba="0.2 0.8 0.2 1"/>
                            </body>
                          </body>

                          <!-- Ring (2 DOF) -->
                          <body name="right_ring_base" pos="0.075 0.008 0.0">
                            <joint name="right_hand_ring_0_joint" axis="0 0 1" range="0 1.4" damping="0.05" armature="0.002" stiffness="0"/>
                            <geom  type="capsule" fromto="0 0 0  0.04 0 0" size="0.008" rgba="0.8 0.8 0.8 1"
                                  density="800" friction="2.0 0.01 0.001" contype="1" conaffinity="1" solimp="0.95 0.99 0.001" solref="0.005 1"/>
                            <geom  type="mesh" mesh="h1_ring_proximal" pos="0.02 0 0" rgba="0.9 0.9 0.9 1"
                                  contype="0" conaffinity="0" density="0"/>
                            <body name="right_ring_mid" pos="0.04 0 0">
                              <joint name="right_hand_ring_1_joint" axis="0 0 1" range="0 1.4" damping="0.05" armature="0.002" stiffness="0"/>
                              <geom  type="capsule" fromto="0 0 0  0.03 0 0" size="0.0075" rgba="0.8 0.8 0.8 1"
                                    density="800" friction="2.0 0.01 0.001" contype="1" conaffinity="1" solimp="0.95 0.99 0.001" solref="0.005 1"/>
                              <geom  type="mesh" mesh="h1_ring_intermediate" pos="0.015 0 0" rgba="0.9 0.9 0.9 1"
                                    contype="0" conaffinity="0" density="0"/>
                              <site name="right_ring_tip" pos="0.03 0 0" size="0.004" type="sphere" rgba="0.2 0.8 0.2 1"/>
                            </body>
                          </body>

                          <!-- Pinky (2 DOF) -->
                          <body name="right_pinky_base" pos="0.075 0.022 0.0">
                            <joint name="right_hand_pinky_0_joint" axis="0 0 1" range="0 1.4" damping="0.05" armature="0.002" stiffness="0"/>
                            <geom  type="capsule" fromto="0 0 0  0.035 0 0" size="0.0075" rgba="0.8 0.8 0.8 1"
                                  density="800" friction="2.0 0.01 0.001" contype="1" conaffinity="1" solimp="0.95 0.99 0.001" solref="0.005 1"/>
                            <geom  type="mesh" mesh="h1_pinky_proximal" pos="0.017 0 0" rgba="0.9 0.9 0.9 1"
                                  contype="0" conaffinity="0" density="0"/>
                            <body name="right_pinky_mid" pos="0.035 0 0">
                              <joint name="right_hand_pinky_1_joint" axis="0 0 1" range="0 1.4" damping="0.05" armature="0.002" stiffness="0"/>
                              <geom  type="capsule" fromto="0 0 0  0.028 0 0" size="0.007" rgba="0.8 0.8 0.8 1"
                                    density="800" friction="2.0 0.01 0.001" contype="1" conaffinity="1" solimp="0.95 0.99 0.001" solref="0.005 1"/>
                              <geom  type="mesh" mesh="h1_pinky_intermediate" pos="0.014 0 0" rgba="0.9 0.9 0.9 1"
                                    contype="0" conaffinity="0" density="0"/>
                              <site name="right_pinky_tip" pos="0.028 0 0" size="0.004" type="sphere" rgba="0.2 0.8 0.2 1"/>
                            </body>
                          </body>
                          <!-- ========= END RIGHT HAND ========= -->
                        </body>
                      </body>
                    </body>
                  </body>
                </body>
              </body>
            </body>
            <!-- ================= END ARMS ================= -->
          </body>
        </body>
      </body>
    </body>
  </worldbody>

  <!-- Weld base to world -->
  <equality>
    <weld body1="pelvis" body2="world_anchor" solref="0.002 1" solimp="0.9 0.95 0.001"/>
  </equality>

  <!-- Actuators: arms + both 12-DOF hands -->
  <actuator>
    <!-- Left arm -->
    <motor name="left_shoulder_pitch_joint" joint="left_shoulder_pitch_joint"/>
    <motor name="left_shoulder_roll_joint"  joint="left_shoulder_roll_joint"/>
    <motor name="left_shoulder_yaw_joint"   joint="left_shoulder_yaw_joint"/>
    <motor name="left_elbow_joint"          joint="left_elbow_joint"/>
    <motor name="left_wrist_roll_joint"     joint="left_wrist_roll_joint"/>
    <motor name="left_wrist_pitch_joint"    joint="left_wrist_pitch_joint"/>
    <motor name="left_wrist_yaw_joint"      joint="left_wrist_yaw_joint"/>

    <!-- Left hand: 12 joints -->
    <motor name="left_hand_thumb_0_joint" joint="left_hand_thumb_0_joint"/>
    <motor name="left_hand_thumb_1_joint" joint="left_hand_thumb_1_joint"/>
    <motor name="left_hand_thumb_2_joint" joint="left_hand_thumb_2_joint"/>
    <motor name="left_hand_thumb_3_joint" joint="left_hand_thumb_3_joint"/>
    <motor name="left_hand_index_0_joint" joint="left_hand_index_0_joint"/>
    <motor name="left_hand_index_1_joint" joint="left_hand_index_1_joint"/>
    <motor name="left_hand_middle_0_joint" joint="left_hand_middle_0_joint"/>
    <motor name="left_hand_middle_1_joint" joint="left_hand_middle_1_joint"/>
    <motor name="left_hand_ring_0_joint" joint="left_hand_ring_0_joint"/>
    <motor name="left_hand_ring_1_joint" joint="left_hand_ring_1_joint"/>
    <motor name="left_hand_pinky_0_joint" joint="left_hand_pinky_0_joint"/>
    <motor name="left_hand_pinky_1_joint" joint="left_hand_pinky_1_joint"/>

    <!-- Right arm -->
    <motor name="right_shoulder_pitch_joint" joint="right_shoulder_pitch_joint"/>
    <motor name="right_shoulder_roll_joint"  joint="right_shoulder_roll_joint"/>
    <motor name="right_shoulder_yaw_joint"   joint="right_shoulder_yaw_joint"/>
    <motor name="right_elbow_joint"          joint="right_elbow_joint"/>
    <motor name="right_wrist_roll_joint"     joint="right_wrist_roll_joint"/>
    <motor name="right_wrist_pitch_joint"    joint="right_wrist_pitch_joint"/>
    <motor name="right_wrist_yaw_joint"      joint="right_wrist_yaw_joint"/>

    <!-- Right hand: 12 joints -->
    <motor name="right_hand_thumb_0_joint" joint="right_hand_thumb_0_joint"/>
    <motor name="right_hand_thumb_1_joint" joint="right_hand_thumb_1_joint"/>
    <motor name="right_hand_thumb_2_joint" joint="right_hand_thumb_2_joint"/>
    <motor name="right_hand_thumb_3_joint" joint="right_hand_thumb_3_joint"/>
    <motor name="right_hand_index_0_joint" joint="right_hand_index_0_joint"/>
    <motor name="right_hand_index_1_joint" joint="right_hand_index_1_joint"/>
    <motor name="right_hand_middle_0_joint" joint="right_hand_middle_0_joint"/>
    <motor name="right_hand_middle_1_joint" joint="right_hand_middle_1_joint"/>
    <motor name="right_hand_ring_0_joint" joint="right_hand_ring_0_joint"/>
    <motor name="right_hand_ring_1_joint" joint="right_hand_ring_1_joint"/>
    <motor name="right_hand_pinky_0_joint" joint="right_hand_pinky_0_joint"/>
    <motor name="right_hand_pinky_1_joint" joint="right_hand_pinky_1_joint"/>
  </actuator>

  <!-- IMU sensors (unchanged) -->
  <sensor>
    <gyro name="imu-torso-angular-velocity" site="imu_in_torso" noise="5e-4" cutoff="34.9"/>
    <accelerometer name="imu-torso-linear-acceleration" site="imu_in_torso" noise="1e-2" cutoff="157"/>
    <gyro name="imu-pelvis-angular-velocity" site="imu_in_pelvis" noise="5e-4" cutoff="34.9"/>
    <accelerometer name="imu-pelvis-linear-acceleration" site="imu_in_pelvis" noise="1e-2" cutoff="157"/>
  </sensor>
</mujoco>